<?xml version="1.0" encoding="UTF-8"?>
<testng-results skipped="0" failed="11" ignored="0" total="20" passed="9">
  <reporter-output>
    <line>
      <![CDATA[[INFO] : Assertion Passed : Not able to add duplicate number]]>
    </line>
    <line>
      <![CDATA[[INFO] : Assertion Passed : Can handle remove parameter if collection is empty]]>
    </line>
    <line>
      <![CDATA[[INFO] : Assertion Passed : Add New Entry functionality is working fine]]>
    </line>
    <line>
      <![CDATA[[INFO] : Assertion Passed : Not able to add duplicate number]]>
    </line>
    <line>
      <![CDATA[[INFO] : Assertion Passed : Able to read collection]]>
    </line>
    <line>
      <![CDATA[[INFO] : Assertion Passed : Can handle remove parameter if collection is empty]]>
    </line>
    <line>
      <![CDATA[[INFO] : Assertion Passed : Collection length is correct]]>
    </line>
    <line>
      <![CDATA[[INFO] : Assertion Passed : Function returns position of entry in collection]]>
    </line>
    <line>
      <![CDATA[[INFO] : Assertion Passed : Function returns -1 if entry is not present]]>
    </line>
  </reporter-output>
  <suite name="Default suite" duration-ms="93" started-at="2018-07-09T08:15:52Z" finished-at="2018-07-09T08:15:52Z">
    <groups>
    </groups>
    <test name="Default test" duration-ms="93" started-at="2018-07-09T08:15:52Z" finished-at="2018-07-09T08:15:52Z">
      <class name="testquestion2.Test_MyCollection">
        <test-method status="FAIL" signature="Test10_Rotate_Array()[pri:0, instance:testquestion2.Test_MyCollection@482f8f11]" name="Test10_Rotate_Array" duration-ms="11" started-at="2018-07-09T08:15:52Z" description="Left Rotation Collection Functionality" finished-at="2018-07-09T08:15:52Z">
          <exception class="java.lang.AssertionError">
            <message>
              <![CDATA[expected [{Is, Always, A Fun., Sometimes, Automation, Testing}] but found [question2.MyCollection@369f73a2]]]>
            </message>
            <full-stacktrace>
              <![CDATA[java.lang.AssertionError: expected [{Is, Always, A Fun., Sometimes, Automation, Testing}] but found [question2.MyCollection@369f73a2]
at org.testng.Assert.fail(Assert.java:96)
at org.testng.Assert.failNotEquals(Assert.java:776)
at org.testng.Assert.assertEqualsImpl(Assert.java:137)
at org.testng.Assert.assertEquals(Assert.java:118)
at org.testng.Assert.assertEquals(Assert.java:453)
at org.testng.Assert.assertEquals(Assert.java:463)
at testquestion2.Test_MyCollection.Test10_Rotate_Array(Test_MyCollection.java:94)
at sun.reflect.NativeMethodAccessorImpl.invoke0(Native Method)
at sun.reflect.NativeMethodAccessorImpl.invoke(NativeMethodAccessorImpl.java:62)
at sun.reflect.DelegatingMethodAccessorImpl.invoke(DelegatingMethodAccessorImpl.java:43)
at java.lang.reflect.Method.invoke(Method.java:498)
at org.testng.internal.MethodInvocationHelper.invokeMethod(MethodInvocationHelper.java:124)
at org.testng.internal.Invoker.invokeMethod(Invoker.java:583)
at org.testng.internal.Invoker.invokeTestMethod(Invoker.java:719)
at org.testng.internal.Invoker.invokeTestMethods(Invoker.java:989)
at org.testng.internal.TestMethodWorker.invokeTestMethods(TestMethodWorker.java:125)
at org.testng.internal.TestMethodWorker.run(TestMethodWorker.java:109)
at org.testng.TestRunner.privateRun(TestRunner.java:648)
at org.testng.TestRunner.run(TestRunner.java:505)
at org.testng.SuiteRunner.runTest(SuiteRunner.java:455)
at org.testng.SuiteRunner.runSequentially(SuiteRunner.java:450)
at org.testng.SuiteRunner.privateRun(SuiteRunner.java:415)
at org.testng.SuiteRunner.run(SuiteRunner.java:364)
at org.testng.SuiteRunnerWorker.runSuite(SuiteRunnerWorker.java:52)
at org.testng.SuiteRunnerWorker.run(SuiteRunnerWorker.java:84)
at org.testng.TestNG.runSuitesSequentially(TestNG.java:1208)
at org.testng.TestNG.runSuitesLocally(TestNG.java:1137)
at org.testng.TestNG.runSuites(TestNG.java:1049)
at org.testng.TestNG.run(TestNG.java:1017)
at org.testng.remote.AbstractRemoteTestNG.run(AbstractRemoteTestNG.java:114)
at org.testng.remote.RemoteTestNG.initAndRun(RemoteTestNG.java:251)
at org.testng.remote.RemoteTestNG.main(RemoteTestNG.java:77)
]]>
            </full-stacktrace>
          </exception> <!-- java.lang.AssertionError -->
          <reporter-output>
          </reporter-output>
        </test-method> <!-- Test10_Rotate_Array -->
        <test-method status="FAIL" signature="Test1_Able_To_Add_New_Entry_In_Collection()[pri:0, instance:testquestion2.Test_MyCollection@482f8f11]" name="Test1_Able_To_Add_New_Entry_In_Collection" duration-ms="1" started-at="2018-07-09T08:15:52Z" description="Check Add functionality" finished-at="2018-07-09T08:15:52Z">
          <exception class="java.lang.AssertionError">
            <message>
              <![CDATA[Assertion Failed : Not able to add number 5 in collection expected [true] but found [false]]]>
            </message>
            <full-stacktrace>
              <![CDATA[java.lang.AssertionError: Assertion Failed : Not able to add number 5 in collection expected [true] but found [false]
at org.testng.Assert.fail(Assert.java:96)
at org.testng.Assert.failNotEquals(Assert.java:776)
at org.testng.Assert.assertTrue(Assert.java:44)
at testquestion2.Test_MyCollection.Test1_Able_To_Add_New_Entry_In_Collection(Test_MyCollection.java:16)
at sun.reflect.NativeMethodAccessorImpl.invoke0(Native Method)
at sun.reflect.NativeMethodAccessorImpl.invoke(NativeMethodAccessorImpl.java:62)
at sun.reflect.DelegatingMethodAccessorImpl.invoke(DelegatingMethodAccessorImpl.java:43)
at java.lang.reflect.Method.invoke(Method.java:498)
at org.testng.internal.MethodInvocationHelper.invokeMethod(MethodInvocationHelper.java:124)
at org.testng.internal.Invoker.invokeMethod(Invoker.java:583)
at org.testng.internal.Invoker.invokeTestMethod(Invoker.java:719)
at org.testng.internal.Invoker.invokeTestMethods(Invoker.java:989)
at org.testng.internal.TestMethodWorker.invokeTestMethods(TestMethodWorker.java:125)
at org.testng.internal.TestMethodWorker.run(TestMethodWorker.java:109)
at org.testng.TestRunner.privateRun(TestRunner.java:648)
at org.testng.TestRunner.run(TestRunner.java:505)
at org.testng.SuiteRunner.runTest(SuiteRunner.java:455)
at org.testng.SuiteRunner.runSequentially(SuiteRunner.java:450)
at org.testng.SuiteRunner.privateRun(SuiteRunner.java:415)
at org.testng.SuiteRunner.run(SuiteRunner.java:364)
at org.testng.SuiteRunnerWorker.runSuite(SuiteRunnerWorker.java:52)
at org.testng.SuiteRunnerWorker.run(SuiteRunnerWorker.java:84)
at org.testng.TestNG.runSuitesSequentially(TestNG.java:1208)
at org.testng.TestNG.runSuitesLocally(TestNG.java:1137)
at org.testng.TestNG.runSuites(TestNG.java:1049)
at org.testng.TestNG.run(TestNG.java:1017)
at org.testng.remote.AbstractRemoteTestNG.run(AbstractRemoteTestNG.java:114)
at org.testng.remote.RemoteTestNG.initAndRun(RemoteTestNG.java:251)
at org.testng.remote.RemoteTestNG.main(RemoteTestNG.java:77)
]]>
            </full-stacktrace>
          </exception> <!-- java.lang.AssertionError -->
          <reporter-output>
          </reporter-output>
        </test-method> <!-- Test1_Able_To_Add_New_Entry_In_Collection -->
        <test-method status="PASS" signature="Test2_Duplicate_Entry_In_Collection()[pri:0, instance:testquestion2.Test_MyCollection@482f8f11]" name="Test2_Duplicate_Entry_In_Collection" duration-ms="1" started-at="2018-07-09T08:15:52Z" description="Check Add functionality" finished-at="2018-07-09T08:15:52Z">
          <reporter-output>
            <line>
              <![CDATA[[INFO] : Assertion Passed : Not able to add duplicate number]]>
            </line>
          </reporter-output>
        </test-method> <!-- Test2_Duplicate_Entry_In_Collection -->
        <test-method status="FAIL" signature="Test3_Get_Collection_Functionality()[pri:0, instance:testquestion2.Test_MyCollection@482f8f11]" name="Test3_Get_Collection_Functionality" duration-ms="1" started-at="2018-07-09T08:15:52Z" description="Check toString function" finished-at="2018-07-09T08:15:52Z">
          <exception class="java.lang.AssertionError">
            <message>
              <![CDATA[Assertion Failed : Not able to read collection expected [{}] but found [question2.MyCollection@7fac631b]]]>
            </message>
            <full-stacktrace>
              <![CDATA[java.lang.AssertionError: Assertion Failed : Not able to read collection expected [{}] but found [question2.MyCollection@7fac631b]
at org.testng.Assert.fail(Assert.java:96)
at org.testng.Assert.failNotEquals(Assert.java:776)
at org.testng.Assert.assertEqualsImpl(Assert.java:137)
at org.testng.Assert.assertEquals(Assert.java:118)
at org.testng.Assert.assertEquals(Assert.java:453)
at testquestion2.Test_MyCollection.Test3_Get_Collection_Functionality(Test_MyCollection.java:32)
at sun.reflect.NativeMethodAccessorImpl.invoke0(Native Method)
at sun.reflect.NativeMethodAccessorImpl.invoke(NativeMethodAccessorImpl.java:62)
at sun.reflect.DelegatingMethodAccessorImpl.invoke(DelegatingMethodAccessorImpl.java:43)
at java.lang.reflect.Method.invoke(Method.java:498)
at org.testng.internal.MethodInvocationHelper.invokeMethod(MethodInvocationHelper.java:124)
at org.testng.internal.Invoker.invokeMethod(Invoker.java:583)
at org.testng.internal.Invoker.invokeTestMethod(Invoker.java:719)
at org.testng.internal.Invoker.invokeTestMethods(Invoker.java:989)
at org.testng.internal.TestMethodWorker.invokeTestMethods(TestMethodWorker.java:125)
at org.testng.internal.TestMethodWorker.run(TestMethodWorker.java:109)
at org.testng.TestRunner.privateRun(TestRunner.java:648)
at org.testng.TestRunner.run(TestRunner.java:505)
at org.testng.SuiteRunner.runTest(SuiteRunner.java:455)
at org.testng.SuiteRunner.runSequentially(SuiteRunner.java:450)
at org.testng.SuiteRunner.privateRun(SuiteRunner.java:415)
at org.testng.SuiteRunner.run(SuiteRunner.java:364)
at org.testng.SuiteRunnerWorker.runSuite(SuiteRunnerWorker.java:52)
at org.testng.SuiteRunnerWorker.run(SuiteRunnerWorker.java:84)
at org.testng.TestNG.runSuitesSequentially(TestNG.java:1208)
at org.testng.TestNG.runSuitesLocally(TestNG.java:1137)
at org.testng.TestNG.runSuites(TestNG.java:1049)
at org.testng.TestNG.run(TestNG.java:1017)
at org.testng.remote.AbstractRemoteTestNG.run(AbstractRemoteTestNG.java:114)
at org.testng.remote.RemoteTestNG.initAndRun(RemoteTestNG.java:251)
at org.testng.remote.RemoteTestNG.main(RemoteTestNG.java:77)
]]>
            </full-stacktrace>
          </exception> <!-- java.lang.AssertionError -->
          <reporter-output>
          </reporter-output>
        </test-method> <!-- Test3_Get_Collection_Functionality -->
        <test-method status="FAIL" signature="Test4_DoubleCapacity()[pri:0, instance:testquestion2.Test_MyCollection@482f8f11]" name="Test4_DoubleCapacity" duration-ms="1" started-at="2018-07-09T08:15:52Z" description="Check Overflow Collection" finished-at="2018-07-09T08:15:52Z">
          <exception class="java.lang.AssertionError">
            <message>
              <![CDATA[Assertion Failed : Not able to add number in collection once it get fulled expected [{4,5,-4,-5,6}] but found [question2.MyCollection@5bc79255]]]>
            </message>
            <full-stacktrace>
              <![CDATA[java.lang.AssertionError: Assertion Failed : Not able to add number in collection once it get fulled expected [{4,5,-4,-5,6}] but found [question2.MyCollection@5bc79255]
at org.testng.Assert.fail(Assert.java:96)
at org.testng.Assert.failNotEquals(Assert.java:776)
at org.testng.Assert.assertEqualsImpl(Assert.java:137)
at org.testng.Assert.assertEquals(Assert.java:118)
at org.testng.Assert.assertEquals(Assert.java:453)
at testquestion2.Test_MyCollection.Test4_DoubleCapacity(Test_MyCollection.java:41)
at sun.reflect.NativeMethodAccessorImpl.invoke0(Native Method)
at sun.reflect.NativeMethodAccessorImpl.invoke(NativeMethodAccessorImpl.java:62)
at sun.reflect.DelegatingMethodAccessorImpl.invoke(DelegatingMethodAccessorImpl.java:43)
at java.lang.reflect.Method.invoke(Method.java:498)
at org.testng.internal.MethodInvocationHelper.invokeMethod(MethodInvocationHelper.java:124)
at org.testng.internal.Invoker.invokeMethod(Invoker.java:583)
at org.testng.internal.Invoker.invokeTestMethod(Invoker.java:719)
at org.testng.internal.Invoker.invokeTestMethods(Invoker.java:989)
at org.testng.internal.TestMethodWorker.invokeTestMethods(TestMethodWorker.java:125)
at org.testng.internal.TestMethodWorker.run(TestMethodWorker.java:109)
at org.testng.TestRunner.privateRun(TestRunner.java:648)
at org.testng.TestRunner.run(TestRunner.java:505)
at org.testng.SuiteRunner.runTest(SuiteRunner.java:455)
at org.testng.SuiteRunner.runSequentially(SuiteRunner.java:450)
at org.testng.SuiteRunner.privateRun(SuiteRunner.java:415)
at org.testng.SuiteRunner.run(SuiteRunner.java:364)
at org.testng.SuiteRunnerWorker.runSuite(SuiteRunnerWorker.java:52)
at org.testng.SuiteRunnerWorker.run(SuiteRunnerWorker.java:84)
at org.testng.TestNG.runSuitesSequentially(TestNG.java:1208)
at org.testng.TestNG.runSuitesLocally(TestNG.java:1137)
at org.testng.TestNG.runSuites(TestNG.java:1049)
at org.testng.TestNG.run(TestNG.java:1017)
at org.testng.remote.AbstractRemoteTestNG.run(AbstractRemoteTestNG.java:114)
at org.testng.remote.RemoteTestNG.initAndRun(RemoteTestNG.java:251)
at org.testng.remote.RemoteTestNG.main(RemoteTestNG.java:77)
]]>
            </full-stacktrace>
          </exception> <!-- java.lang.AssertionError -->
          <reporter-output>
          </reporter-output>
        </test-method> <!-- Test4_DoubleCapacity -->
        <test-method status="FAIL" signature="Test5_Remove_Functionality_If_Entry_Already_Present()[pri:0, instance:testquestion2.Test_MyCollection@482f8f11]" name="Test5_Remove_Functionality_If_Entry_Already_Present" duration-ms="1" started-at="2018-07-09T08:15:52Z" description="Check remove functionality" finished-at="2018-07-09T08:15:52Z">
          <exception class="java.lang.AssertionError">
            <message>
              <![CDATA[Assetion Failed : Not Able to delete entry from collection expected [true] but found [false]]]>
            </message>
            <full-stacktrace>
              <![CDATA[java.lang.AssertionError: Assetion Failed : Not Able to delete entry from collection expected [true] but found [false]
at org.testng.Assert.fail(Assert.java:96)
at org.testng.Assert.failNotEquals(Assert.java:776)
at org.testng.Assert.assertTrue(Assert.java:44)
at testquestion2.Test_MyCollection.Test5_Remove_Functionality_If_Entry_Already_Present(Test_MyCollection.java:50)
at sun.reflect.NativeMethodAccessorImpl.invoke0(Native Method)
at sun.reflect.NativeMethodAccessorImpl.invoke(NativeMethodAccessorImpl.java:62)
at sun.reflect.DelegatingMethodAccessorImpl.invoke(DelegatingMethodAccessorImpl.java:43)
at java.lang.reflect.Method.invoke(Method.java:498)
at org.testng.internal.MethodInvocationHelper.invokeMethod(MethodInvocationHelper.java:124)
at org.testng.internal.Invoker.invokeMethod(Invoker.java:583)
at org.testng.internal.Invoker.invokeTestMethod(Invoker.java:719)
at org.testng.internal.Invoker.invokeTestMethods(Invoker.java:989)
at org.testng.internal.TestMethodWorker.invokeTestMethods(TestMethodWorker.java:125)
at org.testng.internal.TestMethodWorker.run(TestMethodWorker.java:109)
at org.testng.TestRunner.privateRun(TestRunner.java:648)
at org.testng.TestRunner.run(TestRunner.java:505)
at org.testng.SuiteRunner.runTest(SuiteRunner.java:455)
at org.testng.SuiteRunner.runSequentially(SuiteRunner.java:450)
at org.testng.SuiteRunner.privateRun(SuiteRunner.java:415)
at org.testng.SuiteRunner.run(SuiteRunner.java:364)
at org.testng.SuiteRunnerWorker.runSuite(SuiteRunnerWorker.java:52)
at org.testng.SuiteRunnerWorker.run(SuiteRunnerWorker.java:84)
at org.testng.TestNG.runSuitesSequentially(TestNG.java:1208)
at org.testng.TestNG.runSuitesLocally(TestNG.java:1137)
at org.testng.TestNG.runSuites(TestNG.java:1049)
at org.testng.TestNG.run(TestNG.java:1017)
at org.testng.remote.AbstractRemoteTestNG.run(AbstractRemoteTestNG.java:114)
at org.testng.remote.RemoteTestNG.initAndRun(RemoteTestNG.java:251)
at org.testng.remote.RemoteTestNG.main(RemoteTestNG.java:77)
]]>
            </full-stacktrace>
          </exception> <!-- java.lang.AssertionError -->
          <reporter-output>
          </reporter-output>
        </test-method> <!-- Test5_Remove_Functionality_If_Entry_Already_Present -->
        <test-method status="PASS" signature="Test6_Remove_Functionality_If_Collection_Is_Empty()[pri:0, instance:testquestion2.Test_MyCollection@482f8f11]" name="Test6_Remove_Functionality_If_Collection_Is_Empty" duration-ms="1" started-at="2018-07-09T08:15:52Z" description="Check remove functionality" finished-at="2018-07-09T08:15:52Z">
          <reporter-output>
            <line>
              <![CDATA[[INFO] : Assertion Passed : Can handle remove parameter if collection is empty]]>
            </line>
          </reporter-output>
        </test-method> <!-- Test6_Remove_Functionality_If_Collection_Is_Empty -->
        <test-method status="FAIL" signature="Test7_Collection_Length_Functionality()[pri:0, instance:testquestion2.Test_MyCollection@482f8f11]" name="Test7_Collection_Length_Functionality" duration-ms="1" started-at="2018-07-09T08:15:52Z" description="Size of Collection" finished-at="2018-07-09T08:15:52Z">
          <exception class="java.lang.AssertionError">
            <message>
              <![CDATA[expected [6] but found [0]]]>
            </message>
            <full-stacktrace>
              <![CDATA[java.lang.AssertionError: expected [6] but found [0]
at org.testng.Assert.fail(Assert.java:96)
at org.testng.Assert.failNotEquals(Assert.java:776)
at org.testng.Assert.assertEqualsImpl(Assert.java:137)
at org.testng.Assert.assertEquals(Assert.java:118)
at org.testng.Assert.assertEquals(Assert.java:652)
at org.testng.Assert.assertEquals(Assert.java:662)
at testquestion2.Test_MyCollection.Test7_Collection_Length_Functionality(Test_MyCollection.java:66)
at sun.reflect.NativeMethodAccessorImpl.invoke0(Native Method)
at sun.reflect.NativeMethodAccessorImpl.invoke(NativeMethodAccessorImpl.java:62)
at sun.reflect.DelegatingMethodAccessorImpl.invoke(DelegatingMethodAccessorImpl.java:43)
at java.lang.reflect.Method.invoke(Method.java:498)
at org.testng.internal.MethodInvocationHelper.invokeMethod(MethodInvocationHelper.java:124)
at org.testng.internal.Invoker.invokeMethod(Invoker.java:583)
at org.testng.internal.Invoker.invokeTestMethod(Invoker.java:719)
at org.testng.internal.Invoker.invokeTestMethods(Invoker.java:989)
at org.testng.internal.TestMethodWorker.invokeTestMethods(TestMethodWorker.java:125)
at org.testng.internal.TestMethodWorker.run(TestMethodWorker.java:109)
at org.testng.TestRunner.privateRun(TestRunner.java:648)
at org.testng.TestRunner.run(TestRunner.java:505)
at org.testng.SuiteRunner.runTest(SuiteRunner.java:455)
at org.testng.SuiteRunner.runSequentially(SuiteRunner.java:450)
at org.testng.SuiteRunner.privateRun(SuiteRunner.java:415)
at org.testng.SuiteRunner.run(SuiteRunner.java:364)
at org.testng.SuiteRunnerWorker.runSuite(SuiteRunnerWorker.java:52)
at org.testng.SuiteRunnerWorker.run(SuiteRunnerWorker.java:84)
at org.testng.TestNG.runSuitesSequentially(TestNG.java:1208)
at org.testng.TestNG.runSuitesLocally(TestNG.java:1137)
at org.testng.TestNG.runSuites(TestNG.java:1049)
at org.testng.TestNG.run(TestNG.java:1017)
at org.testng.remote.AbstractRemoteTestNG.run(AbstractRemoteTestNG.java:114)
at org.testng.remote.RemoteTestNG.initAndRun(RemoteTestNG.java:251)
at org.testng.remote.RemoteTestNG.main(RemoteTestNG.java:77)
]]>
            </full-stacktrace>
          </exception> <!-- java.lang.AssertionError -->
          <reporter-output>
          </reporter-output>
        </test-method> <!-- Test7_Collection_Length_Functionality -->
        <test-method status="FAIL" signature="Test8_Search_Functionality_If_Enrty_Exists()[pri:0, instance:testquestion2.Test_MyCollection@482f8f11]" name="Test8_Search_Functionality_If_Enrty_Exists" duration-ms="8" started-at="2018-07-09T08:15:52Z" description="Search Functionality" finished-at="2018-07-09T08:15:52Z">
          <exception class="java.lang.AssertionError">
            <message>
              <![CDATA[expected [1] but found [0]]]>
            </message>
            <full-stacktrace>
              <![CDATA[java.lang.AssertionError: expected [1] but found [0]
at org.testng.Assert.fail(Assert.java:96)
at org.testng.Assert.failNotEquals(Assert.java:776)
at org.testng.Assert.assertEqualsImpl(Assert.java:137)
at org.testng.Assert.assertEquals(Assert.java:118)
at org.testng.Assert.assertEquals(Assert.java:652)
at org.testng.Assert.assertEquals(Assert.java:662)
at testquestion2.Test_MyCollection.Test8_Search_Functionality_If_Enrty_Exists(Test_MyCollection.java:75)
at sun.reflect.NativeMethodAccessorImpl.invoke0(Native Method)
at sun.reflect.NativeMethodAccessorImpl.invoke(NativeMethodAccessorImpl.java:62)
at sun.reflect.DelegatingMethodAccessorImpl.invoke(DelegatingMethodAccessorImpl.java:43)
at java.lang.reflect.Method.invoke(Method.java:498)
at org.testng.internal.MethodInvocationHelper.invokeMethod(MethodInvocationHelper.java:124)
at org.testng.internal.Invoker.invokeMethod(Invoker.java:583)
at org.testng.internal.Invoker.invokeTestMethod(Invoker.java:719)
at org.testng.internal.Invoker.invokeTestMethods(Invoker.java:989)
at org.testng.internal.TestMethodWorker.invokeTestMethods(TestMethodWorker.java:125)
at org.testng.internal.TestMethodWorker.run(TestMethodWorker.java:109)
at org.testng.TestRunner.privateRun(TestRunner.java:648)
at org.testng.TestRunner.run(TestRunner.java:505)
at org.testng.SuiteRunner.runTest(SuiteRunner.java:455)
at org.testng.SuiteRunner.runSequentially(SuiteRunner.java:450)
at org.testng.SuiteRunner.privateRun(SuiteRunner.java:415)
at org.testng.SuiteRunner.run(SuiteRunner.java:364)
at org.testng.SuiteRunnerWorker.runSuite(SuiteRunnerWorker.java:52)
at org.testng.SuiteRunnerWorker.run(SuiteRunnerWorker.java:84)
at org.testng.TestNG.runSuitesSequentially(TestNG.java:1208)
at org.testng.TestNG.runSuitesLocally(TestNG.java:1137)
at org.testng.TestNG.runSuites(TestNG.java:1049)
at org.testng.TestNG.run(TestNG.java:1017)
at org.testng.remote.AbstractRemoteTestNG.run(AbstractRemoteTestNG.java:114)
at org.testng.remote.RemoteTestNG.initAndRun(RemoteTestNG.java:251)
at org.testng.remote.RemoteTestNG.main(RemoteTestNG.java:77)
]]>
            </full-stacktrace>
          </exception> <!-- java.lang.AssertionError -->
          <reporter-output>
          </reporter-output>
        </test-method> <!-- Test8_Search_Functionality_If_Enrty_Exists -->
        <test-method status="FAIL" signature="Test9_Search_Functionality_If_Enrty_Not_Exists()[pri:0, instance:testquestion2.Test_MyCollection@482f8f11]" name="Test9_Search_Functionality_If_Enrty_Not_Exists" duration-ms="1" started-at="2018-07-09T08:15:52Z" description="Search Functionality" finished-at="2018-07-09T08:15:52Z">
          <exception class="java.lang.AssertionError">
            <message>
              <![CDATA[expected [-1] but found [0]]]>
            </message>
            <full-stacktrace>
              <![CDATA[java.lang.AssertionError: expected [-1] but found [0]
at org.testng.Assert.fail(Assert.java:96)
at org.testng.Assert.failNotEquals(Assert.java:776)
at org.testng.Assert.assertEqualsImpl(Assert.java:137)
at org.testng.Assert.assertEquals(Assert.java:118)
at org.testng.Assert.assertEquals(Assert.java:652)
at org.testng.Assert.assertEquals(Assert.java:662)
at testquestion2.Test_MyCollection.Test9_Search_Functionality_If_Enrty_Not_Exists(Test_MyCollection.java:84)
at sun.reflect.NativeMethodAccessorImpl.invoke0(Native Method)
at sun.reflect.NativeMethodAccessorImpl.invoke(NativeMethodAccessorImpl.java:62)
at sun.reflect.DelegatingMethodAccessorImpl.invoke(DelegatingMethodAccessorImpl.java:43)
at java.lang.reflect.Method.invoke(Method.java:498)
at org.testng.internal.MethodInvocationHelper.invokeMethod(MethodInvocationHelper.java:124)
at org.testng.internal.Invoker.invokeMethod(Invoker.java:583)
at org.testng.internal.Invoker.invokeTestMethod(Invoker.java:719)
at org.testng.internal.Invoker.invokeTestMethods(Invoker.java:989)
at org.testng.internal.TestMethodWorker.invokeTestMethods(TestMethodWorker.java:125)
at org.testng.internal.TestMethodWorker.run(TestMethodWorker.java:109)
at org.testng.TestRunner.privateRun(TestRunner.java:648)
at org.testng.TestRunner.run(TestRunner.java:505)
at org.testng.SuiteRunner.runTest(SuiteRunner.java:455)
at org.testng.SuiteRunner.runSequentially(SuiteRunner.java:450)
at org.testng.SuiteRunner.privateRun(SuiteRunner.java:415)
at org.testng.SuiteRunner.run(SuiteRunner.java:364)
at org.testng.SuiteRunnerWorker.runSuite(SuiteRunnerWorker.java:52)
at org.testng.SuiteRunnerWorker.run(SuiteRunnerWorker.java:84)
at org.testng.TestNG.runSuitesSequentially(TestNG.java:1208)
at org.testng.TestNG.runSuitesLocally(TestNG.java:1137)
at org.testng.TestNG.runSuites(TestNG.java:1049)
at org.testng.TestNG.run(TestNG.java:1017)
at org.testng.remote.AbstractRemoteTestNG.run(AbstractRemoteTestNG.java:114)
at org.testng.remote.RemoteTestNG.initAndRun(RemoteTestNG.java:251)
at org.testng.remote.RemoteTestNG.main(RemoteTestNG.java:77)
]]>
            </full-stacktrace>
          </exception> <!-- java.lang.AssertionError -->
          <reporter-output>
          </reporter-output>
        </test-method> <!-- Test9_Search_Functionality_If_Enrty_Not_Exists -->
      </class> <!-- testquestion2.Test_MyCollection -->
      <class name="testquestion1.Test_MyCollection">
        <test-method status="FAIL" signature="Test10_Rotate_Array()[pri:0, instance:testquestion1.Test_MyCollection@1593948d]" name="Test10_Rotate_Array" duration-ms="2" started-at="2018-07-09T08:15:52Z" description="Left Rotation Collection Functionality" finished-at="2018-07-09T08:15:52Z">
          <exception class="java.lang.ArrayIndexOutOfBoundsException">
            <message>
              <![CDATA[15]]>
            </message>
            <full-stacktrace>
              <![CDATA[java.lang.ArrayIndexOutOfBoundsException: 15
at question1.MyCollection.rotate(MyCollection.java:106)
at testquestion1.Test_MyCollection.Test10_Rotate_Array(Test_MyCollection.java:92)
at sun.reflect.NativeMethodAccessorImpl.invoke0(Native Method)
at sun.reflect.NativeMethodAccessorImpl.invoke(NativeMethodAccessorImpl.java:62)
at sun.reflect.DelegatingMethodAccessorImpl.invoke(DelegatingMethodAccessorImpl.java:43)
at java.lang.reflect.Method.invoke(Method.java:498)
at org.testng.internal.MethodInvocationHelper.invokeMethod(MethodInvocationHelper.java:124)
at org.testng.internal.Invoker.invokeMethod(Invoker.java:583)
at org.testng.internal.Invoker.invokeTestMethod(Invoker.java:719)
at org.testng.internal.Invoker.invokeTestMethods(Invoker.java:989)
at org.testng.internal.TestMethodWorker.invokeTestMethods(TestMethodWorker.java:125)
at org.testng.internal.TestMethodWorker.run(TestMethodWorker.java:109)
at org.testng.TestRunner.privateRun(TestRunner.java:648)
at org.testng.TestRunner.run(TestRunner.java:505)
at org.testng.SuiteRunner.runTest(SuiteRunner.java:455)
at org.testng.SuiteRunner.runSequentially(SuiteRunner.java:450)
at org.testng.SuiteRunner.privateRun(SuiteRunner.java:415)
at org.testng.SuiteRunner.run(SuiteRunner.java:364)
at org.testng.SuiteRunnerWorker.runSuite(SuiteRunnerWorker.java:52)
at org.testng.SuiteRunnerWorker.run(SuiteRunnerWorker.java:84)
at org.testng.TestNG.runSuitesSequentially(TestNG.java:1208)
at org.testng.TestNG.runSuitesLocally(TestNG.java:1137)
at org.testng.TestNG.runSuites(TestNG.java:1049)
at org.testng.TestNG.run(TestNG.java:1017)
at org.testng.remote.AbstractRemoteTestNG.run(AbstractRemoteTestNG.java:114)
at org.testng.remote.RemoteTestNG.initAndRun(RemoteTestNG.java:251)
at org.testng.remote.RemoteTestNG.main(RemoteTestNG.java:77)
]]>
            </full-stacktrace>
          </exception> <!-- java.lang.ArrayIndexOutOfBoundsException -->
          <reporter-output>
          </reporter-output>
        </test-method> <!-- Test10_Rotate_Array -->
        <test-method status="PASS" signature="Test1_Able_To_Add_New_Entry_In_Collection()[pri:0, instance:testquestion1.Test_MyCollection@1593948d]" name="Test1_Able_To_Add_New_Entry_In_Collection" duration-ms="1" started-at="2018-07-09T08:15:52Z" description="Check Add functionality" finished-at="2018-07-09T08:15:52Z">
          <reporter-output>
            <line>
              <![CDATA[[INFO] : Assertion Passed : Add New Entry functionality is working fine]]>
            </line>
          </reporter-output>
        </test-method> <!-- Test1_Able_To_Add_New_Entry_In_Collection -->
        <test-method status="PASS" signature="Test2_Duplicate_Entry_In_Collection()[pri:0, instance:testquestion1.Test_MyCollection@1593948d]" name="Test2_Duplicate_Entry_In_Collection" duration-ms="1" started-at="2018-07-09T08:15:52Z" description="Check Add functionality" finished-at="2018-07-09T08:15:52Z">
          <reporter-output>
            <line>
              <![CDATA[[INFO] : Assertion Passed : Not able to add duplicate number]]>
            </line>
          </reporter-output>
        </test-method> <!-- Test2_Duplicate_Entry_In_Collection -->
        <test-method status="PASS" signature="Test3_Get_Collection_Functionality()[pri:0, instance:testquestion1.Test_MyCollection@1593948d]" name="Test3_Get_Collection_Functionality" duration-ms="1" started-at="2018-07-09T08:15:52Z" description="Check toString function" finished-at="2018-07-09T08:15:52Z">
          <reporter-output>
            <line>
              <![CDATA[[INFO] : Assertion Passed : Able to read collection]]>
            </line>
          </reporter-output>
        </test-method> <!-- Test3_Get_Collection_Functionality -->
        <test-method status="FAIL" signature="Test4_DoubleCapacity()[pri:0, instance:testquestion1.Test_MyCollection@1593948d]" name="Test4_DoubleCapacity" duration-ms="1" started-at="2018-07-09T08:15:52Z" description="Check Overflow Collection" finished-at="2018-07-09T08:15:52Z">
          <exception class="java.lang.AssertionError">
            <message>
              <![CDATA[Assertion Failed : Not able to add number in collection once it get fulled expected [{4,5,-4,-5,6}] but found [{}]]]>
            </message>
            <full-stacktrace>
              <![CDATA[java.lang.AssertionError: Assertion Failed : Not able to add number in collection once it get fulled expected [{4,5,-4,-5,6}] but found [{}]
at org.testng.Assert.fail(Assert.java:96)
at org.testng.Assert.failNotEquals(Assert.java:776)
at org.testng.Assert.assertEqualsImpl(Assert.java:137)
at org.testng.Assert.assertEquals(Assert.java:118)
at org.testng.Assert.assertEquals(Assert.java:453)
at testquestion1.Test_MyCollection.Test4_DoubleCapacity(Test_MyCollection.java:40)
at sun.reflect.NativeMethodAccessorImpl.invoke0(Native Method)
at sun.reflect.NativeMethodAccessorImpl.invoke(NativeMethodAccessorImpl.java:62)
at sun.reflect.DelegatingMethodAccessorImpl.invoke(DelegatingMethodAccessorImpl.java:43)
at java.lang.reflect.Method.invoke(Method.java:498)
at org.testng.internal.MethodInvocationHelper.invokeMethod(MethodInvocationHelper.java:124)
at org.testng.internal.Invoker.invokeMethod(Invoker.java:583)
at org.testng.internal.Invoker.invokeTestMethod(Invoker.java:719)
at org.testng.internal.Invoker.invokeTestMethods(Invoker.java:989)
at org.testng.internal.TestMethodWorker.invokeTestMethods(TestMethodWorker.java:125)
at org.testng.internal.TestMethodWorker.run(TestMethodWorker.java:109)
at org.testng.TestRunner.privateRun(TestRunner.java:648)
at org.testng.TestRunner.run(TestRunner.java:505)
at org.testng.SuiteRunner.runTest(SuiteRunner.java:455)
at org.testng.SuiteRunner.runSequentially(SuiteRunner.java:450)
at org.testng.SuiteRunner.privateRun(SuiteRunner.java:415)
at org.testng.SuiteRunner.run(SuiteRunner.java:364)
at org.testng.SuiteRunnerWorker.runSuite(SuiteRunnerWorker.java:52)
at org.testng.SuiteRunnerWorker.run(SuiteRunnerWorker.java:84)
at org.testng.TestNG.runSuitesSequentially(TestNG.java:1208)
at org.testng.TestNG.runSuitesLocally(TestNG.java:1137)
at org.testng.TestNG.runSuites(TestNG.java:1049)
at org.testng.TestNG.run(TestNG.java:1017)
at org.testng.remote.AbstractRemoteTestNG.run(AbstractRemoteTestNG.java:114)
at org.testng.remote.RemoteTestNG.initAndRun(RemoteTestNG.java:251)
at org.testng.remote.RemoteTestNG.main(RemoteTestNG.java:77)
]]>
            </full-stacktrace>
          </exception> <!-- java.lang.AssertionError -->
          <reporter-output>
          </reporter-output>
        </test-method> <!-- Test4_DoubleCapacity -->
        <test-method status="FAIL" signature="Test5_Remove_Functionality_If_Entry_Already_Present()[pri:0, instance:testquestion1.Test_MyCollection@1593948d]" name="Test5_Remove_Functionality_If_Entry_Already_Present" duration-ms="1" started-at="2018-07-09T08:15:52Z" description="Check remove functionality" finished-at="2018-07-09T08:15:52Z">
          <exception class="java.lang.AssertionError">
            <message>
              <![CDATA[Assetion Failed : Not Able to delete entry from collection expected [true] but found [false]]]>
            </message>
            <full-stacktrace>
              <![CDATA[java.lang.AssertionError: Assetion Failed : Not Able to delete entry from collection expected [true] but found [false]
at org.testng.Assert.fail(Assert.java:96)
at org.testng.Assert.failNotEquals(Assert.java:776)
at org.testng.Assert.assertTrue(Assert.java:44)
at testquestion1.Test_MyCollection.Test5_Remove_Functionality_If_Entry_Already_Present(Test_MyCollection.java:49)
at sun.reflect.NativeMethodAccessorImpl.invoke0(Native Method)
at sun.reflect.NativeMethodAccessorImpl.invoke(NativeMethodAccessorImpl.java:62)
at sun.reflect.DelegatingMethodAccessorImpl.invoke(DelegatingMethodAccessorImpl.java:43)
at java.lang.reflect.Method.invoke(Method.java:498)
at org.testng.internal.MethodInvocationHelper.invokeMethod(MethodInvocationHelper.java:124)
at org.testng.internal.Invoker.invokeMethod(Invoker.java:583)
at org.testng.internal.Invoker.invokeTestMethod(Invoker.java:719)
at org.testng.internal.Invoker.invokeTestMethods(Invoker.java:989)
at org.testng.internal.TestMethodWorker.invokeTestMethods(TestMethodWorker.java:125)
at org.testng.internal.TestMethodWorker.run(TestMethodWorker.java:109)
at org.testng.TestRunner.privateRun(TestRunner.java:648)
at org.testng.TestRunner.run(TestRunner.java:505)
at org.testng.SuiteRunner.runTest(SuiteRunner.java:455)
at org.testng.SuiteRunner.runSequentially(SuiteRunner.java:450)
at org.testng.SuiteRunner.privateRun(SuiteRunner.java:415)
at org.testng.SuiteRunner.run(SuiteRunner.java:364)
at org.testng.SuiteRunnerWorker.runSuite(SuiteRunnerWorker.java:52)
at org.testng.SuiteRunnerWorker.run(SuiteRunnerWorker.java:84)
at org.testng.TestNG.runSuitesSequentially(TestNG.java:1208)
at org.testng.TestNG.runSuitesLocally(TestNG.java:1137)
at org.testng.TestNG.runSuites(TestNG.java:1049)
at org.testng.TestNG.run(TestNG.java:1017)
at org.testng.remote.AbstractRemoteTestNG.run(AbstractRemoteTestNG.java:114)
at org.testng.remote.RemoteTestNG.initAndRun(RemoteTestNG.java:251)
at org.testng.remote.RemoteTestNG.main(RemoteTestNG.java:77)
]]>
            </full-stacktrace>
          </exception> <!-- java.lang.AssertionError -->
          <reporter-output>
          </reporter-output>
        </test-method> <!-- Test5_Remove_Functionality_If_Entry_Already_Present -->
        <test-method status="PASS" signature="Test6_Remove_Functionality_If_Collection_Is_Empty()[pri:0, instance:testquestion1.Test_MyCollection@1593948d]" name="Test6_Remove_Functionality_If_Collection_Is_Empty" duration-ms="0" started-at="2018-07-09T08:15:52Z" description="Check remove functionality" finished-at="2018-07-09T08:15:52Z">
          <reporter-output>
            <line>
              <![CDATA[[INFO] : Assertion Passed : Can handle remove parameter if collection is empty]]>
            </line>
          </reporter-output>
        </test-method> <!-- Test6_Remove_Functionality_If_Collection_Is_Empty -->
        <test-method status="PASS" signature="Test7_Collection_Length_Functionality()[pri:0, instance:testquestion1.Test_MyCollection@1593948d]" name="Test7_Collection_Length_Functionality" duration-ms="1" started-at="2018-07-09T08:15:52Z" description="Size of Collection" finished-at="2018-07-09T08:15:52Z">
          <reporter-output>
            <line>
              <![CDATA[[INFO] : Assertion Passed : Collection length is correct]]>
            </line>
          </reporter-output>
        </test-method> <!-- Test7_Collection_Length_Functionality -->
        <test-method status="PASS" signature="Test8_Search_Functionality_If_Enrty_Exists()[pri:0, instance:testquestion1.Test_MyCollection@1593948d]" name="Test8_Search_Functionality_If_Enrty_Exists" duration-ms="1" started-at="2018-07-09T08:15:52Z" description="Search Functionality" finished-at="2018-07-09T08:15:52Z">
          <reporter-output>
            <line>
              <![CDATA[[INFO] : Assertion Passed : Function returns position of entry in collection]]>
            </line>
          </reporter-output>
        </test-method> <!-- Test8_Search_Functionality_If_Enrty_Exists -->
        <test-method status="PASS" signature="Test9_Search_Functionality_If_Enrty_Not_Exists()[pri:0, instance:testquestion1.Test_MyCollection@1593948d]" name="Test9_Search_Functionality_If_Enrty_Not_Exists" duration-ms="1" started-at="2018-07-09T08:15:52Z" description="Search Functionality" finished-at="2018-07-09T08:15:52Z">
          <reporter-output>
            <line>
              <![CDATA[[INFO] : Assertion Passed : Function returns -1 if entry is not present]]>
            </line>
          </reporter-output>
        </test-method> <!-- Test9_Search_Functionality_If_Enrty_Not_Exists -->
      </class> <!-- testquestion1.Test_MyCollection -->
    </test> <!-- Default test -->
  </suite> <!-- Default suite -->
</testng-results>
